time 0ms: Simulator started for FCFS [Q <empty>]
time 0ms: Process B arrived and added to ready queue [Q A B]
time 0ms: Process A arrived and added to ready queue [Q A]
time 4.0ms: Process A started using the CPU [Q B]
time 172ms: Process A completed a CPU burst; 4 bursts to go [Q B]
time 172ms: Process A switching out of CPU; will block on I/O until time 463ms [Q B]
time 180.0ms: Process B started using the CPU [Q <empty>]
time 190ms: Process C arrived and added to ready queue [Q C]
time 250ms: Process D arrived and added to ready queue [Q C D]
time 463ms: Process A completed I/O; added to ready queue [Q C D A]
time 565ms: Process B terminated [Q C D A]
time 573.0ms: Process C started using the CPU [Q D A]
time 670ms: Process C completed a CPU burst; 4 bursts to go [Q D A]
time 670ms: Process C switching out of CPU; will block on I/O until time 3173ms [Q D A]
time 678.0ms: Process D started using the CPU [Q A]
time 2448ms: Process D completed a CPU burst; 1 burst to go [Q A]
time 2448ms: Process D switching out of CPU; will block on I/O until time 3274ms [Q A]
time 2456.0ms: Process A started using the CPU [Q <empty>]
time 2624ms: Process A completed a CPU burst; 3 bursts to go [Q <empty>]
time 2624ms: Process A switching out of CPU; will block on I/O until time 2915ms [Q <empty>]
time 2915ms: Process A completed I/O; added to ready queue [Q A]
time 2919.0ms: Process A started using the CPU [Q <empty>]
time 3087ms: Process A completed a CPU burst; 2 bursts to go [Q <empty>]
time 3087ms: Process A switching out of CPU; will block on I/O until time 3378ms [Q <empty>]
time 3173ms: Process C completed I/O; added to ready queue [Q C]
time 3177.0ms: Process C started using the CPU [Q <empty>]
time 3274ms: Process C completed a CPU burst; 3 bursts to go [Q D]
time 3274ms: Process C switching out of CPU; will block on I/O until time 5777ms [Q D]
time 3274ms: Process D completed I/O; added to ready queue [Q D]
time 3282.0ms: Process D started using the CPU [Q <empty>]
time 3378ms: Process A completed I/O; added to ready queue [Q A]
time 5052ms: Process D terminated [Q A]
time 5060.0ms: Process A started using the CPU [Q <empty>]
time 5228ms: Process A completed a CPU burst; 1 burst to go [Q <empty>]
time 5228ms: Process A switching out of CPU; will block on I/O until time 5519ms [Q <empty>]
time 5519ms: Process A completed I/O; added to ready queue [Q A]
time 5523.0ms: Process A started using the CPU [Q <empty>]
time 5691ms: Process A terminated [Q <empty>]
time 5777ms: Process C completed I/O; added to ready queue [Q C]
time 5781.0ms: Process C started using the CPU [Q <empty>]
time 5878ms: Process C completed a CPU burst; 2 bursts to go [Q <empty>]
time 5878ms: Process C switching out of CPU; will block on I/O until time 8381ms [Q <empty>]
time 8381ms: Process C completed I/O; added to ready queue [Q C]
time 8385.0ms: Process C started using the CPU [Q <empty>]
time 8482ms: Process C completed a CPU burst; 1 burst to go [Q <empty>]
time 8482ms: Process C switching out of CPU; will block on I/O until time 10985ms [Q <empty>]
time 10985ms: Process C completed I/O; added to ready queue [Q C]
time 10989.0ms: Process C started using the CPU [Q <empty>]
time 11086ms: Process C terminated [Q <empty>]
time 11090ms: Simulator ended for FCFS
time 0ms: Simulator started for SRT [Q <empty>]
time 0ms: Process B arrived and added to ready queue [Q A B]

time 0ms: Process A arrived and added to ready queue [Q A]
time 4.0ms: Process A started using the CPU [Q B]
time 172ms: Process A completed a CPU burst; 4 bursts to go [Q B]
time 172ms: Process A switching out of CPU; will block on I/O until time 463ms [Q B]
time 180.0ms: Process B started using the CPU [Q <empty>]
time 190ms: Process B started using the CPU with 375ms remaining [Q C]
time 190ms: Process C arrived and will preempt B [Q <empty>]
time 195ms: Process B completed I/O; added to ready queue [Q B]
time 198.0ms: Process C started using the CPU [Q B]
time 250ms: Process D arrived and added to ready queue [Q B D]
time 295ms: Process C completed a CPU burst; 4 bursts to go [Q B D]
time 295ms: Process C switching out of CPU; will block on I/O until time 2798ms [Q B D]
time 303.0ms: Process B started using the CPU [Q D]
time 463ms: Process B started using the CPU with 215ms remaining [Q A D]
time 463ms: Process A completed I/O and will preempt B [Q D]
time 468ms: Process B completed I/O; added to ready queue [Q B D]
time 471.0ms: Process A started using the CPU [Q B D]
time 639ms: Process A completed a CPU burst; 3 bursts to go [Q B D]
time 639ms: Process A switching out of CPU; will block on I/O until time 930ms [Q B D]
time 647.0ms: Process B started using the CPU [Q D]
time 862ms: Process B terminated [Q D]
time 870.0ms: Process D started using the CPU [Q <empty>]
time 930ms: Process D started using the CPU with 1710ms remaining [Q A]
time 930ms: Process A completed I/O and will preempt D [Q <empty>]
time 935ms: Process D completed I/O; added to ready queue [Q D]
time 938.0ms: Process A started using the CPU [Q D]
time 1106ms: Process A completed a CPU burst; 2 bursts to go [Q D]
time 1106ms: Process A switching out of CPU; will block on I/O until time 1397ms [Q D]
time 1114.0ms: Process D started using the CPU [Q <empty>]
time 1397ms: Process D started using the CPU with 1427ms remaining [Q A]
time 1397ms: Process A completed I/O and will preempt D [Q <empty>]
time 1402ms: Process D completed I/O; added to ready queue [Q D]
time 1405.0ms: Process A started using the CPU [Q D]
time 1573ms: Process A completed a CPU burst; 1 burst to go [Q D]
time 1573ms: Process A switching out of CPU; will block on I/O until time 1864ms [Q D]
time 1581.0ms: Process D started using the CPU [Q <empty>]
time 1864ms: Process D started using the CPU with 1144ms remaining [Q A]
time 1864ms: Process A completed I/O and will preempt D [Q <empty>]
time 1869ms: Process D completed I/O; added to ready queue [Q D]
time 1872.0ms: Process A started using the CPU [Q D]
time 2040ms: Process A terminated [Q D]
time 2048.0ms: Process D started using the CPU [Q <empty>]
time 2798ms: Process D started using the CPU with 394ms remaining [Q C]
time 2798ms: Process C completed I/O and will preempt D [Q <empty>]
time 2803ms: Process D completed I/O; added to ready queue [Q D]
time 2806.0ms: Process C started using the CPU [Q D]
time 2903ms: Process C completed a CPU burst; 3 bursts to go [Q D]
time 2903ms: Process C switching out of CPU; will block on I/O until time 5406ms [Q D]
time 2911.0ms: Process D started using the CPU [Q <empty>]
time 3305ms: Process D completed a CPU burst; 1 burst to go [Q <empty>]
time 3305ms: Process D switching out of CPU; will block on I/O until time 4131ms [Q <empty>]
time 4131ms: Process D completed I/O; added to ready queue [Q D]
time 4135.0ms: Process D started using the CPU [Q <empty>]
time 5406ms: Process D started using the CPU with 499ms remaining [Q C]
time 5406ms: Process C completed I/O and will preempt D [Q <empty>]
time 5411ms: Process D completed I/O; added to ready queue [Q D]
time 5414.0ms: Process C started using the CPU [Q D]
time 5511ms: Process C completed a CPU burst; 2 bursts to go [Q D]
time 5511ms: Process C switching out of CPU; will block on I/O until time 8014ms [Q D]
time 5519.0ms: Process D started using the CPU [Q <empty>]
time 6018ms: Process D terminated [Q <empty>]
time 8014ms: Process C completed I/O; added to ready queue [Q C]
time 8018.0ms: Process C started using the CPU [Q <empty>]
time 8115ms: Process C completed a CPU burst; 1 burst to go [Q <empty>]
time 8115ms: Process C switching out of CPU; will block on I/O until time 10618ms [Q <empty>]
time 10618ms: Process C completed I/O; added to ready queue [Q C]
time 10622.0ms: Process C started using the CPU [Q <empty>]
time 10719ms: Process C terminated [Q <empty>]
time 10723ms: Simulator ended for SRT
